<?xml version="1.0" encoding="utf-8"?>
<!-- This URDF was automatically created by SolidWorks to URDF Exporter! Originally created by Stephen Brawner (brawner@gmail.com) 
     Commit Version: 1.6.0-1-g15f4949  Build Version: 1.6.7594.29634
     For more information, please see http://wiki.ros.org/sw_urdf_exporter -->

<robot xmlns:xacro="http://ros.org/wiki/xacro" name="full_model">

    <xacro:include filename="$(find macro_tutorial)/src/model/model.urdf.xacro"/>
    <xacro:include filename="$(find gripper_pkg)/urdf/grip.urdf.xacro"/>


    <xacro:rotating_base/>
    <xacro:gripper/>
    
    <joint name="attachment" type="revolute">
        <origin xyz="0.0 0.1 0.125" rpy="0.0 0.0 0.0"/>
        <parent link="inter_2"/>
        <child link="grip_body"/>
	<axis xyz="0 0 1"/>
        <limit effort="30" velocity="1.0" lower="-0.45" upper="0.45" />    
    </joint>


</robot>
