<?xml version="1.0"?>


<robot name="myfirst">
  
  <link name="ground_frame">
    <origin xyz="0.0 0.0 0.0" rpy="0.0 0.0 0.0"/>
  </link>

  <link name="base_link">
    <origin xyz="0.0 0.0 -0.3" rpy="0.0 0.0 0.0"/>
    <visual>
      <geometry>
        <cylinder length="0.6" radius="0.2"/>
      </geometry>
    </visual>
  </link>

  <joint name="rev1" type="revolute">
    <origin xyz="0.0 0.0 -0.0" rpy="0.0 0.0 0.0"/>
    <parent link="ground_frame"/>
    <child link="base_link"/>
    <axis xyz="0.0 1.0 0.0"/>
    <limit lower="0.0" upper="30.0" effort="30.0" velocity="2.0"/>
  </joint>
</robot>